Workbook

Sheet Terms 
A1: Settlement | B1: 40130 | D1: Cost | E1: 10183896
A2: Maturity | B2: 42687 | D2: Face Value | E2: 11120346
A3: Rate | B3: 0.13 | D3: Discount | E3: =E2-E1 -> 936450.23
A4: Price | B4: =+E1/E2*100 -> 91.578947
A5: Redemption | B5: 100
A6: Coupon Frequency | B6: 4
A7: Day Basis | B7: 0
A8: Yield | B8: =YIELD(B1,B2,B3,B4,B5,B6,B7) -> 0.14961419

Sheet Carry Value Proof 
A1: Day Basis = 30/360 | E1: 0.15821962 | J1: Day Basis = 30/360 | L1: =+L3+K3 -> 936450.23
A2: Date | B2: Cash Flow | C2: Face Value | D2: Carry Value | E2: Effective Interest Rate | F2: Disc Amortization | J2: Date | K2: Cash Flow | L2: Face Value | M2: Carry Value | N2: Effective Interest Rate | P2: Disc Amortization
A3: 40130 | B3: -10183896 | C3: 11120346 | D3: 10183896 | E3: =+E1 -> 0.15821962 | J3: 40130 | K3: -10183896 | L3: 11120346 | M3: 10183896 | N3: ='get Rates'!F21 -> 0.14263631
A4: 40222 | B4: 361411.26 | D4: =+D3+F4 -> 10225308 | F4: =(0.25*$E$3*D3)-B4 -> 41411.778 | J4: 40222 | K4: 361411.26 | M4: =+M3+P4 -> 10185633 | N4: ='get Rates'!G21 -> 0.14308542 | P4: =(0.25*N3*M3)-K4 -> 1737.085
A5: 40311 | B5: 361411.26 | D5: =+D4+F5 -> 10268358 | F5: =(0.25*$E$3*D4)-B5 -> 43049.817 | J5: 40311 | K5: 361411.26 | M5: =+M4+P5 -> 10188576 | N5: ='get Rates'!H21 -> 0.14353391 | P5: =(0.25*N4*M4)-K5 -> 2942.6496
A6: 40403 | B6: 361411.26 | D6: =+D5+F6 -> 10313110 | F6: =(0.25*$E$3*D5)-B6 -> 44752.648 | J6: 40403 | K6: 361411.26 | M6: =+M5+P6 -> 10192766 | N6: ='get Rates'!I21 -> 0.14401625 | P6: =(0.25*N5*M5)-K6 -> 4190.2798
A7: 40495 | B7: 361411.26 | D7: =+D6+F7 -> 10359633 | F7: =(0.25*$E$3*D6)-B7 -> 46522.835 | J7: 40495 | K7: 361411.26 | M7: =+M6+P7 -> 10198336 | N7: ='get Rates'!J21 -> 0.14451651 | P7: =(0.25*N6*M6)-K7 -> 5569.7257
A8: 40587 | B8: 361411.26 | D8: =+D7+F8 -> 10407996 | F8: =(0.25*$E$3*D7)-B8 -> 48363.041 | J8: 40587 | K8: 361411.26 | M8: =+M7+P8 -> 10205382 | N8: ='get Rates'!K21 -> 0.14503541 | P8: =(0.25*N7*M7)-K8 -> 7045.7129
A9: 40676 | B9: 361411.26 | D9: =+D8+F9 -> 10458272 | F9: =(0.25*$E$3*D8)-B9 -> 50276.037 | J9: 40676 | K9: 361411.26 | M9: =+M8+P9 -> 10214006 | N9: ='get Rates'!L21 -> 0.14555032 | P9: =(0.25*N8*M8)-K9 -> 8624.1795
A10: 40768 | B10: 361411.26 | D10: =+D9+F10 -> 10510537 | F10: =(0.25*$E$3*D9)-B10 -> 52264.701 | J10: 40768 | K10: 361411.26 | M10: =+M9+P10 -> 10224258 | N10: ='get Rates'!M21 -> 0.14610797 | P10: =(0.25*N9*M9)-K10 -> 10251.69
A11: 40860 | B11: 361411.26 | D11: =+D10+F11 -> 10564869 | F11: =(0.25*$E$3*D10)-B11 -> 54332.026 | J11: 40860 | K11: 361411.26 | M11: =+M10+P11 -> 10236308 | N11: ='get Rates'!N21 -> 0.14668665 | P11: =(0.25*N10*M10)-K11 -> 12050.115
A12: 40952 | B12: 361411.26 | D12: =+D11+F12 -> 10621350 | F12: =(0.25*$E$3*D11)-B12 -> 56481.124 | J12: 40952 | K12: 361411.26 | M12: =+M11+P12 -> 10250279 | N12: ='get Rates'!O21 -> 0.14728727 | P12: =(0.25*N11*M11)-K12 -> 13971.162
A13: 41042 | B13: 361411.26 | D13: =+D12+F13 -> 10680065 | F13: =(0.25*$E$3*D12)-B13 -> 58715.229 | J13: 41042 | K13: 361411.26 | M13: =+M12+P13 -> 10266301 | N13: ='get Rates'!P21 -> 0.14788883 | P13: =(0.25*N12*M12)-K13 -> 16022.636
A14: 41134 | B14: 361411.26 | D14: =+D13+F14 -> 10741103 | F14: =(0.25*$E$3*D13)-B14 -> 61037.705 | J14: 41134 | K14: 361411.26 | M14: =+M13+P14 -> 10284458 | N14: ='get Rates'!Q21 -> 0.14853547 | P14: =(0.25*N13*M13)-K14 -> 18156.561
A15: 41226 | B15: 361411.26 | D15: =+D14+F15 -> 10804555 | F15: =(0.25*$E$3*D14)-B15 -> 63452.045 | J15: 41226 | K15: 361411.26 | M15: =+M14+P15 -> 10304948 | N15: ='get Rates'!R21 -> 0.14920716 | P15: =(0.25*N14*M14)-K15 -> 20490.436
A16: 41318 | B16: 361411.26 | D16: =+D15+F16 -> 10870517 | F16: =(0.25*$E$3*D15)-B16 -> 65961.885 | J16: 41318 | K16: 361411.26 | M16: =+M15+P16 -> 10327930 | N16: ='get Rates'!S21 -> 0.14990513 | P16: =(0.25*N15*M15)-K16 -> 22981.753
A17: 41407 | B17: 361411.26 | D17: =+D16+F17 -> 10939088 | F17: =(0.25*$E$3*D16)-B17 -> 68571.001 | J17: 41407 | K17: 361411.26 | M17: =+M16+P17 -> 10353571 | N17: ='get Rates'!T21 -> 0.15058191 | P17: =(0.25*N16*M16)-K17 -> 25641.17
A18: 41499 | B18: 361411.26 | D18: =+D17+F18 -> 11010371 | F18: =(0.25*$E$3*D17)-B18 -> 71283.32 | J18: 41499 | K18: 361411.26 | M18: =+M17+P18 -> 10381925 | N18: ='get Rates'!U21 -> 0.15133483 | P18: =(0.25*N17*M17)-K18 -> 28353.883
A19: 41591 | B19: 361411.26 | D19: =+D18+F19 -> 11084474 | F19: =(0.25*$E$3*D18)-B19 -> 74102.925 | J19: 41591 | K19: 361411.26 | M19: =+M18+P19 -> 10413301 | N19: ='get Rates'!V21 -> 0.1521186 | P19: =(0.25*N18*M18)-K19 -> 31375.462
A20: 41683 | B20: 361411.26 | D20: =+D19+F20 -> 11161508 | F20: =(0.25*$E$3*D19)-B20 -> 77034.059 | G20: Discount Fully Amortized | J20: 41683 | K20: 361411.26 | M20: =+M19+P20 -> 10447904 | N20: ='get Rates'!W21 -> 0.15293526 | P20: =(0.25*N19*M19)-K20 -> 34602.926
A21: 41772 | B21: 361411.26 | D21: =+D20+F21 -> 11241590 | F21: =(0.25*$E$3*D20)-B21 -> 80081.134 | J21: 41772 | K21: 361411.26 | M21: =+M20+P21 -> 10485956 | N21: ='get Rates'!X21 -> 0.15370834 | P21: =(0.25*N20*M20)-K21 -> 38051.966
A22: 41864 | B22: 361411.26 | D22: =+D21+F22 -> 11324838 | F22: =(0.25*$E$3*D21)-B22 -> 83248.735 | J22: 41864 | K22: 361411.26 | M22: =+M21+P22 -> 10527489 | N22: ='get Rates'!Y21 -> 0.15459542 | P22: =(0.25*N21*M21)-K22 -> 41533.445
A23: 41956 | B23: 361411.26 | D23: =+D22+F23 -> 11411380 | F23: =(0.25*$E$3*D22)-B23 -> 86541.631 | J23: 41956 | K23: 361411.26 | M23: =+M22+P23 -> 10572953 | N23: ='get Rates'!Z21 -> 0.15552443 | P23: =(0.25*N22*M22)-K23 -> 45464.145
A24: 42048 | B24: 361411.26 | D24: =+D23+F24 -> 11501345 | F24: =(0.25*$E$3*D23)-B24 -> 89964.777 | J24: 42048 | K24: 361411.26 | M24: =+M23+P24 -> 10622630 | N24: ='get Rates'!AA21 -> 0.15650042 | P24: =(0.25*N23*M23)-K24 -> 49676.863
A25: 42137 | B25: 361411.26 | D25: =+D24+F25 -> 11594868 | F25: =(0.25*$E$3*D24)-B25 -> 93523.325 | J25: 42137 | K25: 361411.26 | M25: =+M24+P25 -> 10676830 | N25: ='get Rates'!AB21 -> 0.15737838 | P25: =(0.25*N24*M24)-K25 -> 54200.258
A26: 42229 | B26: 361411.26 | D26: =+D25+F26 -> 11692091 | F26: =(0.25*$E$3*D25)-B26 -> 97222.631 | J26: 42229 | K26: 361411.26 | M26: =+M25+P26 -> 10735495 | N26: ='get Rates'!AC21 -> 0.15846674 | P26: =(0.25*N25*M25)-K26 -> 58664.297
A27: 42321 | B27: 361411.26 | D27: =+D26+F27 -> 11793159 | F27: =(0.25*$E$3*D26)-B27 -> 101068.26 | J27: 42321 | K27: 361411.26 | M27: =+M26+P27 -> 10799388 | N27: ='get Rates'!AD21 -> 0.15963766 | P27: =(0.25*N26*M26)-K27 -> 63893.441
A28: 42413 | B28: 361411.26 | D28: =+D27+F28 -> 11898225 | F28: =(0.25*$E$3*D27)-B28 -> 105066.01 | J28: 42413 | K28: 361411.26 | M28: =+M27+P28 -> 10868974 | N28: ='get Rates'!AE21 -> 0.16092627 | P28: =(0.25*N27*M27)-K28 -> 69585.998
A29: 42503 | B29: 361411.26 | D29: =+D28+F29 -> 12007447 | F29: =(0.25*$E$3*D28)-B29 -> 109221.88 | J29: 42503 | K29: 361411.26 | M29: =+M28+P29 -> 10944839 | N29: ='get Rates'!AF21 -> 0.16206075 | P29: =(0.25*N28*M28)-K29 -> 75864.609
A30: 42595 | B30: 361411.26 | D30: =+D29+F30 -> 12120989 | F30: =(0.25*$E$3*D29)-B30 -> 113542.15 | J30: 42595 | K30: 361411.26 | M30: =+M29+P30 -> 11026860 | N30: ='get Rates'!AG21 -> 0.16406142 | P30: =(0.25*N29*M29)-K30 -> 82020.925
A31: 42687 | B31: 361411.26 | D31: =+D30+F31 -> 12239022 | F31: =(0.25*$E$3*D30)-B31 -> 118033.29 | J31: 42687 | K31: 361411.26 | M31: =+M30+P31 -> 11117719 | P31: =(0.25*N30*M30)-K31 -> 90859.287
F32: =SUM(F4:F31) -> 2055126
P33: =SUM(P4:P32) -> 933822.66
P35: =+P33-L1 -> -2627.5682 | Q35: Plug this # to P31

Sheet get Rates
B1: Parameters: | F1: ='Carry Value Proof '!J3 -> 40130 | G1: ='Carry Value Proof '!J4 -> 40222 | H1: ='Carry Value Proof '!J5 -> 40311 | I1: ='Carry Value Proof '!J6 -> 40403 | J1: ='Carry Value Proof '!J7 -> 40495 | K1: ='Carry Value Proof '!J8 -> 40587 | L1: ='Carry Value Proof '!J9 -> 40676 | M1: ='Carry Value Proof '!J10 -> 40768 | N1: ='Carry Value Proof '!J11 -> 40860 | O1: ='Carry Value Proof '!J12 -> 40952 | P1: ='Carry Value Proof '!J13 -> 41042 | Q1: ='Carry Value Proof '!J14 -> 41134 | R1: ='Carry Value Proof '!J15 -> 41226 | S1: ='Carry Value Proof '!J16 -> 41318 | T1: ='Carry Value Proof '!J17 -> 41407 | U1: ='Carry Value Proof '!J18 -> 41499 | V1: ='Carry Value Proof '!J19 -> 41591 | W1: ='Carry Value Proof '!J20 -> 41683 | X1: ='Carry Value Proof '!J21 -> 41772 | Y1: ='Carry Value Proof '!J22 -> 41864 | Z1: ='Carry Value Proof '!J23 -> 41956 | AA1: ='Carry Value Proof '!J24 -> 42048 | AB1: ='Carry Value Proof '!J25 -> 42137 | AC1: ='Carry Value Proof '!J26 -> 42229 | AD1: ='Carry Value Proof '!J27 -> 42321 | AE1: ='Carry Value Proof '!J28 -> 42413 | AF1: ='Carry Value Proof '!J29 -> 42503 | AG1: ='Carry Value Proof '!J30 -> 42595 | AH1: ='Carry Value Proof '!J31 -> 42687
C3: Principal | E3: P | F3: 11120346 | G3: 11120346 | H3: 11120346 | I3: 11120346 | J3: 11120346 | K3: 11120346 | L3: 11120346 | M3: 11120346 | N3: 11120346 | O3: 11120346 | P3: 11120346 | Q3: 11120346 | R3: 11120346 | S3: 11120346 | T3: 11120346 | U3: 11120346 | V3: 11120346 | W3: 11120346 | X3: 11120346 | Y3: 11120346 | Z3: 11120346 | AA3: 11120346 | AB3: 11120346 | AC3: 11120346 | AD3: 11120346 | AE3: 11120346 | AF3: 11120346 | AG3: 11120346 | AH3: 11120346
C4: Carrying Value | E4: CV | F4: ='Carry Value Proof '!M3 -> 10183896 | G4: ='Carry Value Proof '!M4 -> 10185633 | H4: ='Carry Value Proof '!M5 -> 10188576 | I4: ='Carry Value Proof '!M6 -> 10192766 | J4: ='Carry Value Proof '!M7 -> 10198336 | K4: ='Carry Value Proof '!M8 -> 10205382 | L4: ='Carry Value Proof '!M9 -> 10214006 | M4: ='Carry Value Proof '!M10 -> 10224258 | N4: ='Carry Value Proof '!M11 -> 10236308 | O4: ='Carry Value Proof '!M12 -> 10250279 | P4: ='Carry Value Proof '!M13 -> 10266301 | Q4: ='Carry Value Proof '!M14 -> 10284458 | R4: ='Carry Value Proof '!M15 -> 10304948 | S4: ='Carry Value Proof '!M16 -> 10327930 | T4: ='Carry Value Proof '!M17 -> 10353571 | U4: ='Carry Value Proof '!M18 -> 10381925 | V4: ='Carry Value Proof '!M19 -> 10413301 | W4: ='Carry Value Proof '!M20 -> 10447904 | X4: ='Carry Value Proof '!M21 -> 10485956 | Y4: ='Carry Value Proof '!M22 -> 10527489 | Z4: ='Carry Value Proof '!M23 -> 10572953 | AA4: ='Carry Value Proof '!M24 -> 10622630 | AB4: ='Carry Value Proof '!M25 -> 10676830 | AC4: ='Carry Value Proof '!M26 -> 10735495 | AD4: ='Carry Value Proof '!M27 -> 10799388 | AE4: ='Carry Value Proof '!M28 -> 10868974 | AF4: ='Carry Value Proof '!M29 -> 10944839 | AG4: ='Carry Value Proof '!M30 -> 11026860 | AH4: ='Carry Value Proof '!M31 -> 11117719
C5: Settlement date | E5: D1 | F5: 40130 | G5: 40222 | H5: =H1 -> 40311 | I5: =I1 -> 40403 | J5: =J1 -> 40495 | K5: =K1 -> 40587 | L5: =L1 -> 40676 | M5: =M1 -> 40768 | N5: =N1 -> 40860 | O5: =O1 -> 40952 | ... AH5: =AH1 -> 42687
C6: Maturity date | E6: D2 | F6: 42687 | G6: 42687 | H6: 42687 | I6: 42687 | J6: 42687 | K6: 42687 | L6: 42687 | M6: 42687 | N6: 42687 | O6: 42687 | P6: 42687 | Q6: 42687 | R6: 42687 | S6: 42687 | T6: 42687 | U6: 42687 | V6: 42687 | W6: 42687 | X6: 42687 | Y6: 42687 | Z6: 42687 | AA6: 42687 | AB6: 42687 | AC6: 42687 | AD6: 42687 | AE6: 42687 | AF6: 42687 | AG6: 42687 | AH6: 42687
C7: Years to maturity | E7: m | F7: =(F6-F5)/365 -> 7.0054795 | G7: =(G6-G5)/365 -> 6.7534247 | H7: =(H6-H5)/360 -> 6.6 | I7: =(I6-I5)/360 -> 6.3444444 | J7: =(J6-J5)/360 -> 6.0888889 | K7: =(K6-K5)/360 -> 5.8333333 | L7: =(L6-L5)/360 -> 5.5861111 | M7: =(M6-M5)/360 -> 5.3305556 | N7: =(N6-N5)/360 -> 5.075 | O7: =(O6-O5)/360 -> 4.8194444 | ... AH7: =(AH6-AH5)/360 -> 0
C8: Coupon rate | E8: I1 | F8: 0.13 | G8: 0.13 | H8: 0.13 | I8: 0.13 | J8: 0.13 | K8: 0.13 | L8: 0.13 | M8: 0.13 | N8: 0.13 | O8: 0.13 | P8: 0.13 | Q8: 0.13 | R8: 0.13 | S8: 0.13 | T8: 0.13 | U8: 0.13 | V8: 0.13 | W8: 0.13 | X8: 0.13 | Y8: 0.13 | Z8: 0.13 | AA8: 0.13 | AB8: 0.13 | AC8: 0.13 | AD8: 0.13 | AE8: 0.13 | AF8: 0.13 | AG8: 0.13 | AH8: 0.13
C9: PIK rate | E9: I2 | F9: 0 | G9: 0 | H9: 0 | I9: 0 | J9: 0 | K9: 0 | L9: 0 | M9: 0 | N9: 0 | O9: 0 | P9: 0 | Q9: 0 | R9: 0 | S9: 0 | T9: 0 | U9: 0 | V9: 0 | W9: 0 | X9: 0 | Y9: 0 | Z9: 0 | AA9: 0 | AB9: 0 | AC9: 0 | AD9: 0 | AE9: 0 | AF9: 0 | AG9: 0 | AH9: 0
C10: Interest Payment | E10: PMT | F10: =SUM(F8:F9)*F3 -> 1445645 | G10: =SUM(G8:G9)*G3 -> 1445645 | H10: =SUM(H8:H9)*H3 -> 1445645 | I10: =SUM(I8:I9)*I3 -> 1445645 | J10: =SUM(J8:J9)*J3 -> 1445645 | K10: =SUM(K8:K9)*K3 -> 1445645 | L10: =SUM(L8:L9)*L3 -> 1445645 | M10: =SUM(M8:M9)*M3 -> 1445645 | ... AH10: =SUM(AH8:AH9)*AH3 -> 1445645
B12: Method 1 - custom formula (from Main Street Capital)
C13: Already exists as metadata, to be added as optional field with subsequent logic
C15: 1 | D15: P / CV | E15: = A | F15: =F3/F4 -> 1.091954 | G15: =G3/G4 -> 1.0917678 | H15: =H3/H4 -> 1.0914525 | I15: =I3/I4 -> 1.0910038 | J15: =J3/J4 -> 1.0904079 | K15: =K3/K4 -> 1.0896551 | L15: =L3/L4 -> 1.0887351 | M15: =M3/M4 -> 1.0876434 | ... AH15: =AH3/AH4 -> 1.0002363
C16: 2 | D16: (D1 – D2) | F16: =F6-F5 -> 2557 | G16: =G6-G5 -> 2465 | H16: =H6-H5 -> 2376 | I16: =I6-I5 -> 2284 | J16: =J6-J5 -> 2192 | K16: =K6-K5 -> 2100 | L16: =L6-L5 -> 2011 | M16: =M6-M5 -> 1919 | ... AH16: =AH6-AH5 -> 0
C17: 3 | D17: (D1 – D2) / 365 | F17: =F16/365 -> 7.0054795 | G17: =G16/365 -> 6.7534247 | H17: =H16/365 -> 6.509589 | I17: =I16/365 -> 6.2575342 | J17: =J16/365 -> 6.0054795 | K17: =K16/365 -> 5.7534247 | L17: =L16/365 -> 5.509589 | M17: =M16/365 -> 5.2575342 | ... AH17: =AH16/365 -> 0
C18: 4 | D18: 1/[(D1 – D2) / 365] | E18: = B | F18: =1/F17 -> 0.1427454 | G18: =1/G17 -> 0.14807302 | H18: =1/H17 -> 0.15361953 | I18: =1/I17 -> 0.15980736 | J18: =1/J17 -> 0.1665146 | K18: =1/K17 -> 0.17380952 | L18: =1/L17 -> 0.18150174 | M18: =1/M17 -> 0.19020323 | ... AH18: =1/AH17 -> #DIV/0!
C19: 5 | D19: AB | E19: = C | F19: =F15^F18 -> 1.0126363 | G19: =G15^G18 -> 1.0130854 | H19: =H15^H18 -> 1.0135339 | I19: =I15^I18 -> 1.0140162 | J19: =J15^J18 -> 1.0145165 | K19: =K15^K18 -> 1.0150354 | L19: =L15^L18 -> 1.0155503 | M19: =M15^M18 -> 1.016108 | ... AH19: =AH15^AH18 -> #DIV/0!
C20: 6 | D20: I1 + I2 | E20: = D | F20: =F8+F9 -> 0.13 | G20: =G8+G9 -> 0.13 | H20: =H8+H9 -> 0.13 | I20: =I8+I9 -> 0.13 | J20: =J8+J9 -> 0.13 | K20: =K8+K9 -> 0.13 | L20: =L8+L9 -> 0.13 | M20: =M8+M9 -> 0.13 | ... AH20: =AH8+AH9 -> 0.13
C21: 7 | D21: Effective Interest | E21: = C - 1 + D | F21: =F19-1+F20 -> 0.14263631 | G21: =G19-1+G20 -> 0.14308542 | H21: =H19-1+H20 -> 0.14353391 | I21: =I19-1+I20 -> 0.14401625 | J21: =J19-1+J20 -> 0.14451651 | K21: =K19-1+K20 -> 0.14503541 | L21: =L19-1+L20 -> 0.14555032 | M21: =M19-1+M20 -> 0.14610797 | ... AH21: =AH19-1+AH20 -> #DIV/0!
C22: From Log | F22: 0.142641 | G22: 0.143086 | H22: 0.143548 | I22: 0.144026 | J22: 0.144522 | K22: 0.145035 | L22: 0.145568 | M22: 0.14612 | N22: 0.146692 | O22: 0.147285 | P22: 0.147901 | Q22: 0.148539 | R22: 0.149201 | S22: 0.149887 | T22: 0.1506 | U22: 0.15134 | V22: 0.152109 | W22: 0.152908 | X22: 0.153739 | Y22: 0.154604 | Z22: 0.155507 | AA22: 0.156451 | AB22: 0.157441 | AC22: 0.158485 | AD22: 0.159595 | AE22: 0.160797 | AF22: 0.162148 | AG22: 0.163875
C23: Difference | F23: =F21-F22 -> -4.6899349e-06 | G23: =G21-G22 -> -5.7825908e-07 | H23: =H21-H22 -> -1.408864e-05 | I23: =I21-I22 -> -9.7528084e-06 | J23: =J21-J22 -> -5.4929593e-06 | K23: =K21-K22 -> 4.1408975e-07 | L23: =L21-L22 -> -1.7682299e-05 | M23: =M21-M22 -> -1.2031319e-05 | ... AG23: =AG21-AG22 -> 0.00018641509

Sheet Formula Metod defined
A1: Formulas to calculation Effective Interest Metadate:
B2: Effective Yield (DR)
B4: The option for each of these should be on the Income Security panel.
B5: There is a field existing called:
D6: Effective Interest Calculation Methodology
C7: This field has two drop down - PRICE and IRR
C8: The drop down should be extended/amended as follows:
D9: Method 1 (custom formula) - add as new option
D10: Method 2 (PRICE) - retain
D11: Method 3 (generic formula) - add a new option
D12: IRR - remove
B13: The mathematics to calculate the Effective Yield (DR) metadata should be determined on the selection in this field.
C14: If Method 1 is selected, than the formula indicated in method 1 should be used
C15: If Method 2 is selected, than the formula indicated in method 1 should be used
C16: If Method 3 is selected, than the formula indicated in method 1 should be used
B17: If there is a client provided figure in the existing field within the Income Security Panel, than that field should be used as the effective yield, without a need for any calculation
B20: Parameters: | F20: Sample 1 | H20: Sample 1 cont | J20: Test Data Random
C22: Principal | E22: P | F22: 11120346 | H22: 11120346 | J22: 10000000 | M22: The outstanding principal balance of the coupon yielding instrument
C23: Carrying Value | E23: CV | F23: 10183896 | H23: 10185646 | J23: 9000000 | M23: The carrying value of the coupon yielding instrument
C24: Settlement date | E24: D1 | F24: 40130 | H24: 40222 | J24: 41437 | M24: Date the instrument is closed and starts yielding interest
C25: Maturity date | E25: D2 | F25: 42687 | H25: 42687 | J25: 45089 | M25: Date the instrument matures and is due for repayment
C26: Years to maturity | E26: m | F26: =(F25-F24)/365 -> 7.0054795 | H26: =(H25-H24)/365 -> 6.7534247 | J26: =(J25-J24)/360 -> 10.144444
C27: Coupon rate | E27: I1 | F27: 0.13 | H27: 0.13 | J27: 0.1 | M27: Interest rate / coupon of the instrument
C28: PIK rate | E28: I2 | F28: 0 | H28: 0 | J28: 0.05 | M28: Additional interest rate in kind of the instrument
C29: Interest Payment | E29: PMT | F29: =SUM(F27:F28)*F22 -> 1445645 | H29: =SUM(H27:H28)*H22 -> 1445645 | J29: =SUM(J27:J28)*J22 -> 1500000
B31: Method 1 - custom formula (from Main Street Capital)
C32: Already exists as metadata, to be added as optional field with subsequent logic
C34: 1 | D34: P / CV | E34: = A | F34: =F22/F23 -> 1.091954 | H34: =H22/H23 -> 1.0917665 | J34: =J22/J23 -> 1.1111111
C35: 2 | D35: (D1 – D2) | F35: =F25-F24 -> 2557 | H35: =H25-H24 -> 2465 | J35: =J25-J24 -> 3652
C36: 3 | D36: (D1 – D2) / 365 | F36: =F35/365 -> 7.0054795 | H36: =H35/365 -> 6.7534247 | J36: =J35/365 -> 10.005479
C37: 4 | D37: 1/[(D1 – D2) / 365] | E37: = B | F37: =1/F36 -> 0.1427454 | H37: =1/H36 -> 0.14807302 | J37: =1/J36 -> 0.099945235
C38: 5 | D38: AB | E38: = C | F38: =F34^F37 -> 1.0126363 | H38: =H34^H37 -> 1.0130852 | J38: =J34^J37 -> 1.0105859
C39: 6 | D39: I1 + I2 | E39: = D | F39: =F27+F28 -> 0.13 | H39: =H27+H28 -> 0.13 | J39: =J27+J28 -> 0.15
C40: 7 | D40: Effective Interest | E40: = C - 1 + D | F40: =F38-1+F39 -> 0.14263631 | H40: =H38-1+H39 -> 0.14308524 | J40: =J38-1+J39 -> 0.16058592
B44: Method 2 - as in original AT - the PRICE Methodology
D45: Highest priority is terms of calculations methods
D46: Iterations to find the appropriate rate, as per attached file. This exists for the AT, needs to be used in BE
D47: Need to add logic to make this method used (if selected) as calculation for effective yield metadata
B49: Method 3
D50: Next highest priority
...

Sheet using log rates
A1: Day Basis = 30/360 | E1: 0.15821962 | J1: Day Basis = 30/360 | L1: =+L3+K3 -> 936450.23 | Q1: From Log File | S1: From Log File | T1: From Log File
A2: Date | B2: Cash Flow | C2: Face Value | D2: Carry Value | E2: Effective Interest Rate | F2: Disc Amortization | J2: Date | K2: Cash Flow | L2: Face Value | M2: Carry Value | N2: Effective Interest Rate | P2: Disc Amortization | Q2: From Log File | S2: From Log File | T2: From Log File
A3: 40130 | B3: -10183896 | C3: 11120346 | D3: 10183896 | E3: =+E1 -> 0.15821962 | J3: 40130 | K3: -10183896 | L3: 11120346 | M3: 10183896 | N3: =S3 -> 0.142641 | S3: 0.142641 | T3: 10183896
A4: 40222 | B4: 361411.26 | D4: =+D3+F4 -> 10225308 | F4: =(0.25*$E$3*D3)-B4 -> 41411.778 | J4: 40222 | K4: 361411.26 | M4: =+M3+P4 -> 10185645 | N4: =S4 -> 0.143086 | P4: =(0.25*N3*M3)-K4 -> 1749.0255 | Q4: 1749.575 | S4: 0.143086 | T4: 10185646
A5: 40311 | B5: 361411.26 | D5: =+D4+F5 -> 10268358 | F5: =(0.25*$E$3*D4)-B5 -> 43049.817 | J5: 40311 | K5: 361411.26 | M5: =+M4+P5 -> 10188590 | N5: =S5 -> 0.143548 | P5: =(0.25*N4*M4)-K5 -> 2944.5492 | Q5: 2945.8407 | S5: 0.143548 | T5: 10188592
A6: 40403 | B6: 361411.26 | D6: =+D5+F6 -> 10313110 | F6: =(0.25*$E$3*D5)-B6 -> 44752.648 | J6: 40403 | K6: 361411.26 | M6: =+M5+P6 -> 10192816 | N6: =S6 -> 0.144026 | P6: =(0.25*N5*M5)-K6 -> 4226.6623 | Q6: 4226.5832 | S6: 0.144026 | T6: 10192818
A7: 40495 | B7: 361411.26 | D7: =+D6+F7 -> 10359633 | F7: =(0.25*$E$3*D6)-B7 -> 46522.835 | J7: 40495 | K7: 361411.26 | M7: =+M6+P7 -> 10198413 | N7: =S7 -> 0.144522 | P7: =(0.25*N6*M6)-K7 -> 5596.3861 | Q7: 5596.8487 | S7: 0.144522 | T7: 10198415
A8: 40587 | B8: 361411.26 | D8: =+D7+F8 -> 10407996 | F8: =(0.25*$E$3*D7)-B8 -> 48363.041 | J8: 40587 | K8: 361411.26 | M8: =+M7+P8 -> 10205475 | N8: =S8 -> 0.145035 | P8: =(0.25*N7*M7)-K8 -> 7062.4955 | Q8: 7062.0067 | S8: 0.145035 | T8: 10205477
A9: 40676 | B9: 361411.26 | D9: =+D8+F9 -> 10458272 | F9: =(0.25*$E$3*D8)-B9 -> 50276.037 | J9: 40676 | K9: 361411.26 | M9: =+M8+P9 -> 10214102 | N9: =S9 -> 0.145568 | P9: =(0.25*N8*M8)-K9 -> 8626.5192 | Q9: 8627.7763 | S9: 0.145568 | T9: 10214105
A10: 40768 | B10: 361411.26 | D10: =+D9+F10 -> 10510537 | F10: =(0.25*$E$3*D9)-B10 -> 52264.701 | J10: 40768 | K10: 361411.26 | M10: =+M9+P10 -> 10224402 | N10: =S10 -> 0.14612 | P10: =(0.25*N9*M9)-K10 -> 10300.335 | Q10: 10300.255 | S10: 0.14612 | T10: 10224405
A11: 40860 | B11: 361411.26 | D11: =+D10+F11 -> 10564869 | F11: =(0.25*$E$3*D10)-B11 -> 54332.026 | J11: 40860 | K11: 361411.26 | M11: =+M10+P11 -> 10236488 | N11: =S11 -> 0.146692 | P11: =(0.25*N10*M10)-K11 -> 12086.152 | Q11: 12085.951 | S11: 0.146692 | T11: 10236491
A12: 40952 | B12: 361411.26 | D12: =+D11+F12 -> 10621350 | F12: =(0.25*$E$3*D11)-B12 -> 56481.124 | J12: 40952 | K12: 361411.26 | M12: =+M11+P12 -> 10250480 | N12: =S12 -> 0.147285 | P12: =(0.25*N11*M11)-K12 -> 13991.477 | Q12: 13991.822 | S12: 0.147285 | T12: 10250483
A13: 41042 | B13: 361411.26 | D13: =+D12+F13 -> 10680065 | F13: =(0.25*$E$3*D12)-B13 -> 58715.229 | J13: 41042 | K13: 361411.26 | M13: =+M12+P13 -> 10266504 | N13: =S13 -> 0.147901 | P13: =(0.25*N12*M12)-K13 -> 16024.22 | Q13: 16025.312 | S13: 0.147901 | T13: 10266508
A14: 41134 | B14: 361411.26 | D14: =+D13+F14 -> 10741103 | F14: =(0.25*$E$3*D13)-B14 -> 61037.705 | J14: 41134 | K14: 361411.26 | M14: =+M13+P14 -> 10284699 | N14: =S14 -> 0.148539 | P14: =(0.25*N13*M13)-K14 -> 18195.294 | Q14: 18194.406 | S14: 0.148539 | T14: 10284703
A15: 41226 | B15: 361411.26 | D15: =+D14+F15 -> 10804555 | F15: =(0.25*$E$3*D14)-B15 -> 63452.045 | J15: 41226 | K15: 361411.26 | M15: =+M14+P15 -> 10305208 | N15: =S15 -> 0.149201 | P15: =(0.25*N14*M14)-K15 -> 20508.479 | Q15: 20507.682 | S15: 0.149201 | T15: 10305210
... A19: 41591 | B19: 361411.26 | D19: =+D18+F19 -> 11084474 | F19: =(0.25*$E$3*D18)-B19 -> 74102.925 | J19: 41591 | K19: 361411.26 | M19: =+M18+P19 -> 10413595 | N19: =S19 -> 0.152109 | P19: =(0.25*N18*M18)-K19 -> 31399.128 | Q19: 31399.072 | S19: 0.152109 | T19: 10413597
A20: 41683 | B20: 361411.26 | D20: =+D19+F20 -> 11161508 | F20: =(0.25*$E$3*D19)-B20 -> 77034.059 | G20: Discount Fully Amortized | J20: 41683 | K20: 361411.26 | M20: =+M19+P20 -> 10448184 | N20: =S20 -> 0.152908 | P20: =(0.25*N19*M19)-K20 -> 34589.128 | Q20: 34588.244 | S20: 0.152908 | T20: 10448185
A21: 41772 | B21: 361411.26 | D21: =+D20+F21 -> 11241590 | F21: =(0.25*$E$3*D20)-B21 -> 80081.134 | J21: 41772 | K21: 361411.26 | M21: =+M20+P21 -> 10486176 | N21: =S21 -> 0.153739 | P21: =(0.25*N20*M20)-K21 -> 37991.482 | Q21: 37990.509 | S21: 0.153739 | T21: 10486176
A22: 41864 | B22: 361411.26 | D22: =+D21+F22 -> 11324838 | F22: =(0.25*$E$3*D21)-B22 -> 83248.735 | J22: 41864 | K22: 361411.26 | M22: =+M21+P22 -> 10527798 | N22: =S22 -> 0.154604 | P22: =(0.25*N21*M21)-K22 -> 41622.286 | Q22: 41621.695 | S22: 0.154604 | T22: 10527797
A23: 41956 | B23: 361411.26 | D23: =+D22+F23 -> 11411380 | F23: =(0.25*$E$3*D22)-B23 -> 86541.631 | J23: 41956 | K23: 361411.26 | M23: =+M22+P23 -> 10573297 | N23: =S23 -> 0.155507 | P23: =(0.25*N22*M22)-K23 -> 45498.664 | Q23: 45499.658 | S23: 0.155507 | T23: 10573297
A24: 42048 | B24: 361411.26 | D24: =+D23+F24 -> 11501345 | F24: =(0.25*$E$3*D23)-B24 -> 89964.777 | J24: 42048 | K24: 361411.26 | M24: =+M23+P24 -> 10622941 | N24: =S24 -> 0.156451 | P24: =(0.25*N23*M23)-K24 -> 49644.155 | Q24: 49644.913 | S24: 0.156451 | T24: 10622942
A25: 42137 | B25: 361411.26 | D25: =+D24+F25 -> 11594868 | F25: =(0.25*$E$3*D24)-B25 -> 93523.325 | J25: 42137 | K25: 361411.26 | M25: =+M24+P25 -> 10677022 | N25: =S25 -> 0.157441 | P25: =(0.25*N24*M24)-K25 -> 54081.172 | Q25: 54081.658 | S25: 0.157441 | T25: 10677024
A26: 42229 | B26: 361411.26 | D26: =+D25+F26 -> 11692091 | F26: =(0.25*$E$3*D25)-B26 -> 97222.631 | J26: 42229 | K26: 361411.26 | M26: =+M25+P26 -> 10735861 | N26: =S26 -> 0.158485 | P26: =(0.25*N25*M25)-K26 -> 58838.998 | Q26: 58839.55 | S26: 0.158485 | T26: 10735863
A27: 42321 | B27: 361411.26 | D27: =+D26+F27 -> 11793159 | F27: =(0.25*$E$3*D26)-B27 -> 101068.26 | J27: 42321 | K27: 361411.26 | M27: =+M26+P27 -> 10799818 | N27: =S27 -> 0.159595 | P27: =(0.25*N26*M26)-K27 -> 63956.976 | Q27: 63957.125 | S27: 0.159595 | T27: 10799820
A28: 42413 | B28: 361411.26 | D28: =+D27+F28 -> 11898225 | F28: =(0.25*$E$3*D27)-B28 -> 105066.01 | J28: 42413 | K28: 361411.26 | M28: =+M27+P28 -> 10869306 | N28: =S28 -> 0.160797 | P28: =(0.25*N27*M27)-K28 -> 69487.981 | Q28: 69489.207 | S28: 0.160797 | T28: 10869310
A29: 42503 | B29: 361411.26 | D29: =+D28+F29 -> 12007447 | F29: =(0.25*$E$3*D28)-B29 -> 109221.88 | J29: 42503 | K29: 361411.26 | M29: =+M28+P29 -> 10944833 | N29: =S29 -> 0.162148 | P29: =(0.25*N28*M28)-K29 -> 75526.691 | Q29: 75526.055 | S29: 0.162148 | T29: 10944836
A30: 42595 | B30: 361411.26 | D30: =+D29+F30 -> 12120989 | F30: =(0.25*$E$3*D29)-B30 -> 113542.15 | J30: 42595 | K30: 361411.26 | M30: =+M29+P30 -> 11027092 | N30: =S30 -> 0.163875 | P30: =(0.25*N29*M29)-K30 -> 82259.424 | Q30: 82258.449 | S30: 0.163875 | T30: 11027094
A31: 42687 | B31: 361411.26 | D31: =+D30+F31 -> 12239022 | F31: =(0.25*$E$3*D30)-B31 -> 118033.29 | J31: 42687 | K31: 361411.26 | M31: =+M30+P31 -> 11117447 | P31: =(0.25*N30*M30)-K31 -> 90354.921 | Q31: 93252.407
F32: =SUM(F4:F31) -> 2055126
P33: =SUM(P4:P32) -> 933550.84
P36: =+P33-L1 -> -2899.3854 | Q36: Plug this # to P31
